Workbook

Sheet Dashboard
A1: Credit Card Fraud Detection Dashboard
A3: Transaction Risk Analysis & Fraud Monitoring
A5: Total Transactions | E5: Fraud Transactions | I5: Fraud Rate | M5: Total Transaction Amount
A6: =COUNTA(FraudData[transaction_id]) -> 10000 | E6: =COUNTIF(FraudData[is_fraud],1) -> 151 | I6: =E6/A6 -> 0.0151 | M6: ="₹"&TEXT(SUM(FraudData[amount])/1000000,"0.00")&" M" -> ₹1.76 M
A44: Key Outcomes
A45: Overall Fraud Rate: 1.51% Highest Risk Driver: Device Trust (<30) Highest Amount Risk: Transactions above ₹1,000 Highest Velocity Risk: 5–6 transactions in 24 hours | I45: High-Risk Time: 12 AM–3 AM Strong Location Signal: Location mismatch Weakest Risk Factor: Merchant Category

Sheet Risk_Analysis
A1: Foreign Transaction Analysis | J1: Key Finding
A2: Foreign Transaction | B2: Total Transactions | C2: Fraud Transactions | D2: Fraud Rate | E2: Risk Multiplier | J2: Foreign transactions had a much higher fraud rate than non-foreign transactions.
A3: No | B3: =COUNTIF(FraudData[foreign_transaction],0) -> 9022 | C3: =COUNTIFS(FraudData[foreign_transaction],0,FraudData[is_fraud],1) -> 69 | D3: =C3/B3 -> 0.0076479716 | E3: =D3/MIN($D$3:$D$4) -> 1
A4: Yes | B4: =COUNTIF(FraudData[foreign_transaction],1) -> 978 | C4: =COUNTIFS(FraudData[foreign_transaction],1,FraudData[is_fraud],1) -> 82 | D4: =C4/B4 -> 0.083844581 | E4: =D4/MIN($D$3:$D$4) -> 10.962983
A7: Location Mismatch Analysis
A8: Location Mismatch | B8: Total Transactions | C8: Fraud Transactions | D8: Fraud Rate | E8: Risk Multiplier | J8: Transactions with a location mismatch showed a significantly higher fraud rate.
A9: No | B9: =COUNTIF(FraudData[location_mismatch],0) -> 9143 | C9: =COUNTIFS(FraudData[location_mismatch],0,FraudData[is_fraud],1) -> 79 | D9: =C9/B9 -> 0.00864049 | E9: =D9/MIN($D$9:$D$10) -> 1
A10: Yes | B10: =COUNTIF(FraudData[location_mismatch],1) -> 857 | C10: =COUNTIFS(FraudData[location_mismatch],1,FraudData[is_fraud],1) -> 72 | D10: =C10/B10 -> 0.084014002 | E10: =D10/MIN($D$9:$D$10) -> 9.7232914
A13: Device Trust Score Analysis
A14: Device Trust Range | B14: Total Transactions | C14: Fraud Transactions | D14: Fraud Rate | E14: Risk Multiplier | J14: Lower device trust scores were strongly associated with higher fraud rates.
A15: <30 | B15: =COUNTIF(FraudData[device_trust_score],"<30") -> 681 | C15: =COUNTIFS(FraudData[device_trust_score],"<30",FraudData[is_fraud],1) -> 45 | D15: =C15/B15 -> 0.066079295 | E15: =D15/MIN($D$15:$D$18) -> 21.635463
A16: 30–49 | B16: =COUNTIFS(FraudData[device_trust_score],">=30",FraudData[device_trust_score],"<50") -> 2678 | C16: =COUNTIFS(FraudData[device_trust_score],">=30",FraudData[device_trust_score],"<50",FraudData[is_fraud],1) -> 84 | D16: =C16/B16 -> 0.031366692 | E16: =D16/MIN($D$15:$D$18) -> 10.269978
A17: 50–69 | B17: =COUNTIFS(FraudData[device_trust_score],">=50",FraudData[device_trust_score],"<70") -> 2712 | C17: =COUNTIFS(FraudData[device_trust_score],">=50",FraudData[device_trust_score],"<70",FraudData[is_fraud],1) -> 10 | D17: =C17/B17 -> 0.0036873156 | E17: =D17/MIN($D$15:$D$18) -> 1.2072886
A18: 70+ | B18: =COUNTIF(FraudData[device_trust_score],">=70") -> 3929 | C18: =COUNTIFS(FraudData[device_trust_score],">=70",FraudData[is_fraud],1) -> 12 | D18: =C18/B18 -> 0.0030542123 | E18: =D18/MIN($D$15:$D$18) -> 1
A21: Velocity Analysis
A22: Velocity Range | B22: Total Transactions | C22: Fraud Transactions | D22: Fraud Rate | E22: Risk Multiplier | J22: Fraud rate increased sharply when 5–6 transactions occurred within 24 hours.
A23: 0–2 | B23: =COUNTIF(FraudData[velocity_last_24h],"<3") -> 6734 | C23: =COUNTIFS(FraudData[velocity_last_24h],"<3",FraudData[is_fraud],1) -> 63 | D23: =C23/B23 -> 0.0093555094 | E23: =D23/MIN($D$23:$D$26) -> 1
A24: 3–4 | B24: =COUNTIFS(FraudData[velocity_last_24h],">=3",FraudData[velocity_last_24h],"<5") -> 2719 | C24: =COUNTIFS(FraudData[velocity_last_24h],">=3",FraudData[velocity_last_24h],"<5",FraudData[is_fraud],1) -> 31 | D24: =C24/B24 -> 0.01140125 | E24: =D24/MIN($D$23:$D$26) -> 1.218667
A25: 5–6 | B25: =COUNTIFS(FraudData[velocity_last_24h],">=5",FraudData[velocity_last_24h],"<7") -> 496 | C25: =COUNTIFS(FraudData[velocity_last_24h],">=5",FraudData[velocity_last_24h],"<7",FraudData[is_fraud],1) -> 53 | D25: =C25/B25 -> 0.10685484 | E25: =D25/MIN($D$23:$D$26) -> 11.421595
A26: 7+ | B26: =COUNTIF(FraudData[velocity_last_24h],">=7") -> 51 | C26: =COUNTIFS(FraudData[velocity_last_24h],">=7",FraudData[is_fraud],1) -> 4 | D26: =C26/B26 -> 0.078431373 | E26: =D26/MIN($D$23:$D$26) -> 8.3834423
A29: Transaction Hour Analysis
A30: Transaction Hour | B30: Total Transactions | C30: Fraud Transactions | D30: Fraud Rate | E30: Risk Multiplier | J30: Fraud was highly concentrated between 12 AM and 3 AM.
A31: 0 | B31: =COUNTIF(FraudData[transaction_hour],Risk_Analysis!A31) -> 417 | C31: =COUNTIFS(FraudData[transaction_hour],Risk_Analysis!A31,FraudData[is_fraud],1) -> 37 | D31: =C31/B31 -> 0.088729017 | E31: =D31/_xlfn.MINIFS($D$31:$D$54,$D$31:$D$54,">0") -> 40.63789
A32: 1 | B32: =COUNTIF(FraudData[transaction_hour],Risk_Analysis!A32) -> 425 | C32: =COUNTIFS(FraudData[transaction_hour],Risk_Analysis!A32,FraudData[is_fraud],1) -> 34 | D32: =C32/B32 -> 0.08 | E32: =D32/_xlfn.MINIFS($D$31:$D$54,$D$31:$D$54,">0") -> 36.64
A33: 2 | B33: =COUNTIF(FraudData[transaction_hour],Risk_Analysis!A33) -> 385 | C33: =COUNTIFS(FraudData[transaction_hour],Risk_Analysis!A33,FraudData[is_fraud],1) -> 23 | D33: =C33/B33 -> 0.05974026 | E33: =D33/_xlfn.MINIFS($D$31:$D$54,$D$31:$D$54,">0") -> 27.361039
A34: 3 | B34: =COUNTIF(FraudData[transaction_hour],Risk_Analysis!A34) -> 425 | C34: =COUNTIFS(FraudData[transaction_hour],Risk_Analysis!A34,FraudData[is_fraud],1) -> 27 | D34: =C34/B34 -> 0.063529412 | E34: =D34/_xlfn.MINIFS($D$31:$D$54,$D$31:$D$54,">0") -> 29.096471
A35: 4 | B35: =COUNTIF(FraudData[transaction_hour],Risk_Analysis!A35) -> 384 | C35: =COUNTIFS(FraudData[transaction_hour],Risk_Analysis!A35,FraudData[is_fraud],1) -> 1 | D35: =C35/B35 -> 0.0026041667 | E35: =D35/_xlfn.MINIFS($D$31:$D$54,$D$31:$D$54,">0") -> 1.1927083
A36: 5 | B36: =COUNTIF(FraudData[transaction_hour],Risk_Analysis!A36) -> 419 | C36: =COUNTIFS(FraudData[transaction_hour],Risk_Analysis!A36,FraudData[is_fraud],1) -> 2 | D36: =C36/B36 -> 0.0047732697 | E36: =D36/_xlfn.MINIFS($D$31:$D$54,$D$31:$D$54,">0") -> 2.1861575
A37: 6 | B37: =COUNTIF(FraudData[transaction_hour],Risk_Analysis!A37) -> 413 | C37: =COUNTIFS(FraudData[transaction_hour],Risk_Analysis!A37,FraudData[is_fraud],1) -> 2 | D37: =C37/B37 -> 0.004842615 | E37: =D37/_xlfn.MINIFS($D$31:$D$54,$D$31:$D$54,">0") -> 2.2179177
A38: 7 | B38: =COUNTIF(FraudData[transaction_hour],Risk_Analysis!A38) -> 425 | C38: =COUNTIFS(FraudData[transaction_hour],Risk_Analysis!A38,FraudData[is_fraud],1) -> 0 | D38: =C38/B38 -> 0 | E38: =D38/_xlfn.MINIFS($D$31:$D$54,$D$31:$D$54,">0") -> 0
A39: 8 | B39: =COUNTIF(FraudData[transaction_hour],Risk_Analysis!A39) -> 424 | C39: =COUNTIFS(FraudData[transaction_hour],Risk_Analysis!A39,FraudData[is_fraud],1) -> 3 | D39: =C39/B39 -> 0.0070754717 | E39: =D39/_xlfn.MINIFS($D$31:$D$54,$D$31:$D$54,">0") -> 3.240566
A40: 9 | B40: =COUNTIF(FraudData[transaction_hour],Risk_Analysis!A40) -> 426 | C40: =COUNTIFS(FraudData[transaction_hour],Risk_Analysis!A40,FraudData[is_fraud],1) -> 1 | D40: =C40/B40 -> 0.0023474178 | E40: =D40/_xlfn.MINIFS($D$31:$D$54,$D$31:$D$54,">0") -> 1.0751174
A41: 10 | B41: =COUNTIF(FraudData[transaction_hour],Risk_Analysis!A41) -> 358 | C41: =COUNTIFS(FraudData[transaction_hour],Risk_Analysis!A41,FraudData[is_fraud],1) -> 1 | D41: =C41/B41 -> 0.0027932961 | E41: =D41/_xlfn.MINIFS($D$31:$D$54,$D$31:$D$54,">0") -> 1.2793296
A42: 11 | B42: =COUNTIF(FraudData[transaction_hour],Risk_Analysis!A42) -> 385 | C42: =COUNTIFS(FraudData[transaction_hour],Risk_Analysis!A42,FraudData[is_fraud],1) -> 2 | D42: =C42/B42 -> 0.0051948052 | E42: =D42/_xlfn.MINIFS($D$31:$D$54,$D$31:$D$54,">0") -> 2.3792208
... A54: 23 | B54: =COUNTIF(FraudData[transaction_hour],Risk_Analysis!A54) -> 419 | C54: =COUNTIFS(FraudData[transaction_hour],Risk_Analysis!A54,FraudData[is_fraud],1) -> 3 | D54: =C54/B54 -> 0.0071599045 | E54: =D54/_xlfn.MINIFS($D$31:$D$54,$D$31:$D$54,">0") -> 3.2792363
A56: Amount Analysis
A57: Amount Range | B57: Total Transactions | C57: Fraud Transactions | D57: Fraud Rate | E57: Risk Multiplier | J57: Transactions above ₹1,000 had a much higher fraud rate than other amount ranges.
A58: <100 | B58: =COUNTIF(FraudData[amount],"<100") -> 4338 | C58: =COUNTIFS(FraudData[amount],"<100",FraudData[is_fraud],1) -> 67 | D58: =C58/B58 -> 0.015444905 | E58: =D58/MIN($D$58:$D$61) -> 1.1472385
A59: 100–499 | B59: =COUNTIFS(FraudData[amount],">=100",FraudData[amount],"<500") -> 5051 | C59: =COUNTIFS(FraudData[amount],">=100",FraudData[amount],"<500",FraudData[is_fraud],1) -> 68 | D59: =C59/B59 -> 0.013462681 | E59: =D59/MIN($D$58:$D$61) -> 1
A60: 500–999 | B60: =COUNTIFS(FraudData[amount],">=500",FraudData[amount],"<1000") -> 576 | C60: =COUNTIFS(FraudData[amount],">=500",FraudData[amount],"<1000",FraudData[is_fraud],1) -> 11 | D60: =C60/B60 -> 0.019097222 | E60: =D60/MIN($D$58:$D$61) -> 1.4185304
...

Sheet Risk_Model
A1: Risk Scoring Model
A2: Risk Factor | B2: Condition | C2: Evidence from Analysis | D2: Risk Points | E2: Why These Points?
A3: Foreign Transaction | B3: Yes | C3: 8.38% fraud rate / 10.96× baseline | D3: 3 | E3: Very strong difference from normal transactions, so it gets a high weight.
A4: Foreign Transaction | B4: No | C4: 0.76% fraud rate | D4: 0 | E4: This is the baseline group, so no additional risk points.
A5: Location Mismatch | B5: Yes | C5: 8.40% fraud rate / 9.72× baseline | D5: 3 | E5: Fraud rate is much higher when the location does not match, so it gets a high weight.
A6: Location Mismatch | B6: No | C6: 0.86% fraud rate | D6: 0 | E6: This is the normal/baseline condition, so no extra points.
A7: Device Trust | B7: <30 | C7: 6.61% / 21.64× baseline | D7: 3 | E7: One of the strongest indicators in the dataset, so it gets the maximum points.
A8: Device Trust | B8: 30–49 | C8: 3.14% / 10.27× baseline | D8: 2 | E8: Still a strong relationship with fraud, but weaker than scores below 30.
A9: Device Trust | B9: 50–69 | C9: 0.37% / 1.21× baseline | D9: 1 | E9: Only slightly higher than the baseline, so only a small risk point is added.
A10: Device Trust | B10: 70+ | C10: 0.31% / 1.00× baseline | D10: 0 | E10: Lowest observed fraud rate, so no additional risk points.
A11: Transaction Velocity | B11: 0–2 | C11: 0.94% / 1.00× baseline | D11: 0 | E11: Low transaction frequency does not show additional risk.
A12: Transaction Velocity | B12: 3–4 | C12: 1.14% / 1.21× baseline | D12: 0 | E12: The increase is small, so we don't add meaningful risk points.
A13: Transaction Velocity | B13: 5–6 | C13: 10.69% / 11.37× baseline | D13: 3 | E13: Fraud rate increases sharply, making this a strong risk signal.
A14: Transaction Velocity | B14: 7+ | C14: 7.84% / 8.34× baseline | D14: 2 | E14: Still a strong risk signal, but lower than the 5–6 range.
... A21: Transaction Hour | B21: 08–22 | C21: Low fraud rate | D21: 0 | E21: These hours generally show low fraud rates.
A22: Transaction Hour | B22: 23 | C22: Low fraud rate | D22: 1 | E22: Slightly elevated compared with many daytime hours, so only a minor point is given.
A23: Merchant Category | B23: Grocery | C23: 2.01% / 1.71× baseline | D23: 1 | E23: Grocery has the highest category-level fraud rate, but the difference is relatively small.
A24: Merchant Category | B24: Food | C24: 1.67% / 1.43× baseline | D24: 0 | E24: The difference is not strong enough to justify an additional point.
A25: Merchant Category | B25: Travel | C25: 1.46% / 1.24× baseline | D25: 0 | E25: Only a small difference from the baseline.
A26: Merchant Category | B26: Electronics | C26: 1.25% / 1.07× baseline | D26: 0 | E26: Very close to the baseline.
A27: Merchant Category | B27: Clothing | C27: 1.17% / 1.00× baseline | D27: 0 | E27: Used as the lowest-risk category baseline.
A30: Device Trust Score Analysis
A31: Device Min | B31: Device Max | C31: Risk Points
A32: 0 | B32: 29 | C32: 3
A33: 30 | B33: 49 | C33: 2
A34: 50 | B34: 69 | C34: 1
A35: 70 | B35: 999 | C35: 0
A38: Amount Risk Rules
A39: Amount Min | B39: Amount Max | C39: Risk Points
A40: 0 | B40: 499.99 | C40: 0
A41: 500 | B41: 999.99 | C41: 1
A42: 1000 | B42: 9999.99 | C42: 3
A45: Velocity Risk Rules
A46: Velocity Min | B46: Velocity Max | C46: Risk Points
A47: 0 | B47: 2 | C47: 0
A48: 3 | B48: 4 | C48: 0
A49: 5 | B49: 6 | C49: 3
A50: 7 | B50: 999 | C50: 2
A52: Time Risk Rules
A53: Hour Min | B53: Hour Max | C53: Risk Points
...

Sheet Raw_Data
A1: transaction_id | B1: amount | C1: transaction_hour | D1: merchant_category | E1: foreign_transaction | F1: location_mismatch | G1: device_trust_score | H1: velocity_last_24h | I1: cardholder_age | J1: is_fraud | K1: Amount Risk | L1: Time Risk | M1: Foreign Risk | N1: Location Risk | O1: Device Risk | P1: Velocity Risk | Q1: Merchant Risk | R1: Fraud Risk Score | S1: Risk Level
A2: 1 | B2: 84.47 | C2: 22 | D2: Electronics | E2: 0 | F2: 0 | G2: 66 | H2: 3 | I2: 40 | J2: 0 | K2: =_xlfn.XLOOKUP(FraudData[[#This Row],[amount]],AmountRules[Amount Min],AmountRules[Risk Points],,-1) -> 0 | L2: =_xlfn.XLOOKUP(FraudData[[#This Row],[transaction_hour]],TimeRules[Hour Min],TimeRules[Risk Points],,-1) -> 0 | M2: =_xlfn.XLOOKUP(FraudData[[#This Row],[foreign_transaction]],ForeignRules[Foreign Transaction],ForeignRules[Risk Points],0) -> 0 | N2: =_xlfn.XLOOKUP(FraudData[[#This Row],[location_mismatch]],Table10[Location Mismatch],Table10[Risk Points],0) -> 0 | O2: =_xlfn.XLOOKUP(FraudData[[#This Row],[device_trust_score]],DeviceRules[Device Min],DeviceRules[Risk Points],,-1) -> 1 | P2: =_xlfn.XLOOKUP(FraudData[[#This Row],[velocity_last_24h]],VelocityRules[Velocity Min],VelocityRules[Risk Points],,-1) -> 0 | Q2: =_xlfn.XLOOKUP(FraudData[[#This Row],[merchant_category]],MerchantRules[Merchant Category],MerchantRules[Risk Points],0) -> 0 | R2: =SUM(FraudData[[#This Row],[Amount Risk]:[Merchant Risk]]) -> 1 | S2: {=_xlfn.IFS(FraudData[[#This Row],[Fraud Risk Score]]>=8,"High Risk",FraudData[[#This Row],[Fraud Risk Score]]>=6,"Medium Risk",TRUE,"Low Risk")} -> Low Risk
A3: 2 | B3: 541.82 | C3: 3 | D3: Travel | E3: 1 | F3: 0 | G3: 87 | H3: 1 | I3: 64 | J3: 0 | K3: =_xlfn.XLOOKUP(FraudData[[#This Row],[amount]],AmountRules[Amount Min],AmountRules[Risk Points],,-1) -> 1 | L3: =_xlfn.XLOOKUP(FraudData[[#This Row],[transaction_hour]],TimeRules[Hour Min],TimeRules[Risk Points],,-1) -> 3 | M3: =_xlfn.XLOOKUP(FraudData[[#This Row],[foreign_transaction]],ForeignRules[Foreign Transaction],ForeignRules[Risk Points],0) -> 3 | N3: =_xlfn.XLOOKUP(FraudData[[#This Row],[location_mismatch]],Table10[Location Mismatch],Table10[Risk Points],0) -> 0 | O3: =_xlfn.XLOOKUP(FraudData[[#This Row],[device_trust_score]],DeviceRules[Device Min],DeviceRules[Risk Points],,-1) -> 0 | P3: =_xlfn.XLOOKUP(FraudData[[#This Row],[velocity_last_24h]],VelocityRules[Velocity Min],VelocityRules[Risk Points],,-1) -> 0 | Q3: 0 | R3: =SUM(FraudData[[#This Row],[Amount Risk]:[Merchant Risk]]) -> 7 | S3: {=_xlfn.IFS(FraudData[[#This Row],[Fraud Risk Score]]>=8,"High Risk",FraudData[[#This Row],[Fraud Risk Score]]>=6,"Medium Risk",TRUE,"Low Risk")} -> Medium Risk
A4: 3 | B4: 237.01 | C4: 17 | D4: Grocery | E4: 0 | F4: 0 | G4: 49 | H4: 1 | I4: 61 | J4: 0 | K4: =_xlfn.XLOOKUP(FraudData[[#This Row],[amount]],AmountRules[Amount Min],AmountRules[Risk Points],,-1) -> 0 | L4: =_xlfn.XLOOKUP(FraudData[[#This Row],[transaction_hour]],TimeRules[Hour Min],TimeRules[Risk Points],,-1) -> 0 | M4: =_xlfn.XLOOKUP(FraudData[[#This Row],[foreign_transaction]],ForeignRules[Foreign Transaction],ForeignRules[Risk Points],0) -> 0 | N4: =_xlfn.XLOOKUP(FraudData[[#This Row],[location_mismatch]],Table10[Location Mismatch],Table10[Risk Points],0) -> 0 | O4: =_xlfn.XLOOKUP(FraudData[[#This Row],[device_trust_score]],DeviceRules[Device Min],DeviceRules[Risk Points],,-1) -> 2 | P4: =_xlfn.XLOOKUP(FraudData[[#This Row],[velocity_last_24h]],VelocityRules[Velocity Min],VelocityRules[Risk Points],,-1) -> 0 | Q4: =_xlfn.XLOOKUP(FraudData[[#This Row],[merchant_category]],MerchantRules[Merchant Category],MerchantRules[Risk Points],0) -> 1 | R4: =SUM(FraudData[[#This Row],[Amount Risk]:[Merchant Risk]]) -> 3 | S4: {=_xlfn.IFS(FraudData[[#This Row],[Fraud Risk Score]]>=8,"High Risk",FraudData[[#This Row],[Fraud Risk Score]]>=6,"Medium Risk",TRUE,"Low Risk")} -> Low Risk
A5: 4 | B5: 164.33 | C5: 4 | D5: Grocery | E5: 0 | F5: 1 | G5: 72 | H5: 3 | I5: 34 | J5: 0 | K5: =_xlfn.XLOOKUP(FraudData[[#This Row],[amount]],AmountRules[Amount Min],AmountRules[Risk Points],,-1) -> 0 | L5: =_xlfn.XLOOKUP(FraudData[[#This Row],[transaction_hour]],TimeRules[Hour Min],TimeRules[Risk Points],,-1) -> 0 | M5: =_xlfn.XLOOKUP(FraudData[[#This Row],[foreign_transaction]],ForeignRules[Foreign Transaction],ForeignRules[Risk Points],0) -> 0 | N5: =_xlfn.XLOOKUP(FraudData[[#This Row],[location_mismatch]],Table10[Location Mismatch],Table10[Risk Points],0) -> 3 | O5: =_xlfn.XLOOKUP(FraudData[[#This Row],[device_trust_score]],DeviceRules[Device Min],DeviceRules[Risk Points],,-1) -> 0 | P5: =_xlfn.XLOOKUP(FraudData[[#This Row],[velocity_last_24h]],VelocityRules[Velocity Min],VelocityRules[Risk Points],,-1) -> 0 | Q5: =_xlfn.XLOOKUP(FraudData[[#This Row],[merchant_category]],MerchantRules[Merchant Category],MerchantRules[Risk Points],0) -> 1 | R5: =SUM(FraudData[[#This Row],[Amount Risk]:[Merchant Risk]]) -> 4 | S5: {=_xlfn.IFS(FraudData[[#This Row],[Fraud Risk Score]]>=8,"High Risk",FraudData[[#This Row],[Fraud Risk Score]]>=6,"Medium Risk",TRUE,"Low Risk")} -> Low Risk
A6: 5 | B6: 30.53 | C6: 15 | D6: Food | E6: 0 | F6: 0 | G6: 79 | H6: 0 | I6: 44 | J6: 0 | K6: =_xlfn.XLOOKUP(FraudData[[#This Row],[amount]],AmountRules[Amount Min],AmountRules[Risk Points],,-1) -> 0 | L6: =_xlfn.XLOOKUP(FraudData[[#This Row],[transaction_hour]],TimeRules[Hour Min],TimeRules[Risk Points],,-1) -> 0 | M6: =_xlfn.XLOOKUP(FraudData[[#This Row],[foreign_transaction]],ForeignRules[Foreign Transaction],ForeignRules[Risk Points],0) -> 0 | N6: =_xlfn.XLOOKUP(FraudData[[#This Row],[location_mismatch]],Table10[Location Mismatch],Table10[Risk Points],0) -> 0 | O6: =_xlfn.XLOOKUP(FraudData[[#This Row],[device_trust_score]],DeviceRules[Device Min],DeviceRules[Risk Points],,-1) -> 0 | P6: =_xlfn.XLOOKUP(FraudData[[#This Row],[velocity_last_24h]],VelocityRules[Velocity Min],VelocityRules[Risk Points],,-1) -> 0 | Q6: =_xlfn.XLOOKUP(FraudData[[#This Row],[merchant_category]],MerchantRules[Merchant Category],MerchantRules[Risk Points],0) -> 0 | R6: =SUM(FraudData[[#This Row],[Amount Risk]:[Merchant Risk]]) -> 0 | S6: {=_xlfn.IFS(FraudData[[#This Row],[Fraud Risk Score]]>=8,"High Risk",FraudData[[#This Row],[Fraud Risk Score]]>=6,"Medium Risk",TRUE,"Low Risk")} -> Low Risk
A7: 6 | B7: 30.53 | C7: 13 | D7: Clothing | E7: 0 | F7: 0 | G7: 90 | H7: 2 | I7: 46 | J7: 0 | K7: =_xlfn.XLOOKUP(FraudData[[#This Row],[amount]],AmountRules[Amount Min],AmountRules[Risk Points],,-1) -> 0 | L7: =_xlfn.XLOOKUP(FraudData[[#This Row],[transaction_hour]],TimeRules[Hour Min],TimeRules[Risk Points],,-1) -> 0 | M7: =_xlfn.XLOOKUP(FraudData[[#This Row],[foreign_transaction]],ForeignRules[Foreign Transaction],ForeignRules[Risk Points],0) -> 0 | N7: =_xlfn.XLOOKUP(FraudData[[#This Row],[location_mismatch]],Table10[Location Mismatch],Table10[Risk Points],0) -> 0 | O7: =_xlfn.XLOOKUP(FraudData[[#This Row],[device_trust_score]],DeviceRules[Device Min],DeviceRules[Risk Points],,-1) -> 0 | P7: =_xlfn.XLOOKUP(FraudData[[#This Row],[velocity_last_24h]],VelocityRules[Velocity Min],VelocityRules[Risk Points],,-1) -> 0 | Q7: =_xlfn.XLOOKUP(FraudData[[#This Row],[merchant_category]],MerchantRules[Merchant Category],MerchantRules[Risk Points],0) -> 0 | R7: =SUM(FraudData[[#This Row],[Amount Risk]:[Merchant Risk]]) -> 0 | S7: {=_xlfn.IFS(FraudData[[#This Row],[Fraud Risk Score]]>=8,"High Risk",FraudData[[#This Row],[Fraud Risk Score]]>=6,"Medium Risk",TRUE,"Low Risk")} -> Low Risk
A8: 7 | B8: 10.77 | C8: 18 | D8: Travel | E8: 0 | F8: 0 | G8: 48 | H8: 1 | I8: 28 | J8: 0 | K8: =_xlfn.XLOOKUP(FraudData[[#This Row],[amount]],AmountRules[Amount Min],AmountRules[Risk Points],,-1) -> 0 | L8: =_xlfn.XLOOKUP(FraudData[[#This Row],[transaction_hour]],TimeRules[Hour Min],TimeRules[Risk Points],,-1) -> 0 | M8: =_xlfn.XLOOKUP(FraudData[[#This Row],[foreign_transaction]],ForeignRules[Foreign Transaction],ForeignRules[Risk Points],0) -> 0 | N8: =_xlfn.XLOOKUP(FraudData[[#This Row],[location_mismatch]],Table10[Location Mismatch],Table10[Risk Points],0) -> 0 | O8: =_xlfn.XLOOKUP(FraudData[[#This Row],[device_trust_score]],DeviceRules[Device Min],DeviceRules[Risk Points],,-1) -> 2 | P8: =_xlfn.XLOOKUP(FraudData[[#This Row],[velocity_last_24h]],VelocityRules[Velocity Min],VelocityRules[Risk Points],,-1) -> 0 | Q8: =_xlfn.XLOOKUP(FraudData[[#This Row],[merchant_category]],MerchantRules[Merchant Category],MerchantRules[Risk Points],0) -> 0 | R8: =SUM(FraudData[[#This Row],[Amount Risk]:[Merchant Risk]]) -> 2 | S8: {=_xlfn.IFS(FraudData[[#This Row],[Fraud Risk Score]]>=8,"High Risk",FraudData[[#This Row],[Fraud Risk Score]]>=6,"Medium Risk",TRUE,"Low Risk")} -> Low Risk
A9: 8 | B9: 362.02 | C9: 13 | D9: Electronics | E9: 0 | F9: 0 | G9: 68 | H9: 1 | I9: 40 | J9: 0 | K9: =_xlfn.XLOOKUP(FraudData[[#This Row],[amount]],AmountRules[Amount Min],AmountRules[Risk Points],,-1) -> 0 | L9: =_xlfn.XLOOKUP(FraudData[[#This Row],[transaction_hour]],TimeRules[Hour Min],TimeRules[Risk Points],,-1) -> 0 | M9: =_xlfn.XLOOKUP(FraudData[[#This Row],[foreign_transaction]],ForeignRules[Foreign Transaction],ForeignRules[Risk Points],0) -> 0 | N9: =_xlfn.XLOOKUP(FraudData[[#This Row],[location_mismatch]],Table10[Location Mismatch],Table10[Risk Points],0) -> 0 | O9: =_xlfn.XLOOKUP(FraudData[[#This Row],[device_trust_score]],DeviceRules[Device Min],DeviceRules[Risk Points],,-1) -> 1 | P9: =_xlfn.XLOOKUP(FraudData[[#This Row],[velocity_last_24h]],VelocityRules[Velocity Min],VelocityRules[Risk Points],,-1) -> 0 | Q9: =_xlfn.XLOOKUP(FraudData[[#This Row],[merchant_category]],MerchantRules[Merchant Category],MerchantRules[Risk Points],0) -> 0 | R9: =SUM(FraudData[[#This Row],[Amount Risk]:[Merchant Risk]]) -> 1 | S9: {=_xlfn.IFS(FraudData[[#This Row],[Fraud Risk Score]]>=8,"High Risk",FraudData[[#This Row],[Fraud Risk Score]]>=6,"Medium Risk",TRUE,"Low Risk")} -> Low Risk
A10: 9 | B10: 165.43 | C10: 8 | D10: Grocery | E10: 0 | F10: 0 | G10: 80 | H10: 0 | I10: 21 | J10: 0 | K10: =_xlfn.XLOOKUP(FraudData[[#This Row],[amount]],AmountRules[Amount Min],AmountRules[Risk Points],,-1) -> 0 | L10: =_xlfn.XLOOKUP(FraudData[[#This Row],[transaction_hour]],TimeRules[Hour Min],TimeRules[Risk Points],,-1) -> 0 | M10: =_xlfn.XLOOKUP(FraudData[[#This Row],[foreign_transaction]],ForeignRules[Foreign Transaction],ForeignRules[Risk Points],0) -> 0 | N10: =_xlfn.XLOOKUP(FraudData[[#This Row],[location_mismatch]],Table10[Location Mismatch],Table10[Risk Points],0) -> 0 | O10: =_xlfn.XLOOKUP(FraudData[[#This Row],[device_trust_score]],DeviceRules[Device Min],DeviceRules[Risk Points],,-1) -> 0 | P10: =_xlfn.XLOOKUP(FraudData[[#This Row],[velocity_last_24h]],VelocityRules[Velocity Min],VelocityRules[Risk Points],,-1) -> 0 | Q10: =_xlfn.XLOOKUP(FraudData[[#This Row],[merchant_category]],MerchantRules[Merchant Category],MerchantRules[Risk Points],0) -> 1 | R10: =SUM(FraudData[[#This Row],[Amount Risk]:[Merchant Risk]]) -> 1 | S10: {=_xlfn.IFS(FraudData[[#This Row],[Fraud Risk Score]]>=8,"High Risk",FraudData[[#This Row],[Fraud Risk Score]]>=6,"Medium Risk",TRUE,"Low Risk")} -> Low Risk
A11: 10 | B11: 221.63 | C11: 5 | D11: Grocery | E11: 0 | F11: 0 | G11: 59 | H11: 1 | I11: 34 | J11: 0 | K11: =_xlfn.XLOOKUP(FraudData[[#This Row],[amount]],AmountRules[Amount Min],AmountRules[Risk Points],,-1) -> 0 | L11: =_xlfn.XLOOKUP(FraudData[[#This Row],[transaction_hour]],TimeRules[Hour Min],TimeRules[Risk Points],,-1) -> 0 | M11: =_xlfn.XLOOKUP(FraudData[[#This Row],[foreign_transaction]],ForeignRules[Foreign Transaction],ForeignRules[Risk Points],0) -> 0 | N11: =_xlfn.XLOOKUP(FraudData[[#This Row],[location_mismatch]],Table10[Location Mismatch],Table10[Risk Points],0) -> 0 | O11: =_xlfn.XLOOKUP(FraudData[[#This Row],[device_trust_score]],DeviceRules[Device Min],DeviceRules[Risk Points],,-1) -> 1 | P11: =_xlfn.XLOOKUP(FraudData[[#This Row],[velocity_last_24h]],VelocityRules[Velocity Min],VelocityRules[Risk Points],,-1) -> 0 | Q11: =_xlfn.XLOOKUP(FraudData[[#This Row],[merchant_category]],MerchantRules[Merchant Category],MerchantRules[Risk Points],0) -> 1 | R11: =SUM(FraudData[[#This Row],[Amount Risk]:[Merchant Risk]]) -> 2 | S11: {=_xlfn.IFS(FraudData[[#This Row],[Fraud Risk Score]]>=8,"High Risk",FraudData[[#This Row],[Fraud Risk Score]]>=6,"Medium Risk",TRUE,"Low Risk")} -> Low Risk
A12: 11 | B12: 3.74 | C12: 16 | D12: Grocery | E12: 0 | F12: 0 | G12: 58 | H12: 2 | I12: 28 | J12: 0 | K12: =_xlfn.XLOOKUP(FraudData[[#This Row],[amount]],AmountRules[Amount Min],AmountRules[Risk Points],,-1) -> 0 | L12: =_xlfn.XLOOKUP(FraudData[[#This Row],[transaction_hour]],TimeRules[Hour Min],TimeRules[Risk Points],,-1) -> 0 | M12: =_xlfn.XLOOKUP(FraudData[[#This Row],[foreign_transaction]],ForeignRules[Foreign Transaction],ForeignRules[Risk Points],0) -> 0 | N12: =_xlfn.XLOOKUP(FraudData[[#This Row],[location_mismatch]],Table10[Location Mismatch],Table10[Risk Points],0) -> 0 | O12: =_xlfn.XLOOKUP(FraudData[[#This Row],[device_trust_score]],DeviceRules[Device Min],DeviceRules[Risk Points],,-1) -> 1 | P12: =_xlfn.XLOOKUP(FraudData[[#This Row],[velocity_last_24h]],VelocityRules[Velocity Min],VelocityRules[Risk Points],,-1) -> 0 | Q12: =_xlfn.XLOOKUP(FraudData[[#This Row],[merchant_category]],MerchantRules[Merchant Category],MerchantRules[Risk Points],0) -> 1 | R12: =SUM(FraudData[[#This Row],[Amount Risk]:[Merchant Risk]]) -> 2 | S12: {=_xlfn.IFS(FraudData[[#This Row],[Fraud Risk Score]]>=8,"High Risk",FraudData[[#This Row],[Fraud Risk Score]]>=6,"Medium Risk",TRUE,"Low Risk")} -> Low Risk
A13: 12 | B13: 630.64 | C13: 18 | D13: Clothing | E13: 0 | F13: 0 | G13: 30 | H13: 4 | I13: 25 | J13: 0 | K13: =_xlfn.XLOOKUP(FraudData[[#This Row],[amount]],AmountRules[Amount Min],AmountRules[Risk Points],,-1) -> 1 | L13: =_xlfn.XLOOKUP(FraudData[[#This Row],[transaction_hour]],TimeRules[Hour Min],TimeRules[Risk Points],,-1) -> 0 | M13: =_xlfn.XLOOKUP(FraudData[[#This Row],[foreign_transaction]],ForeignRules[Foreign Transaction],ForeignRules[Risk Points],0) -> 0 | N13: =_xlfn.XLOOKUP(FraudData[[#This Row],[location_mismatch]],Table10[Location Mismatch],Table10[Risk Points],0) -> 0 | O13: =_xlfn.XLOOKUP(FraudData[[#This Row],[device_trust_score]],DeviceRules[Device Min],DeviceRules[Risk Points],,-1) -> 2 | P13: =_xlfn.XLOOKUP(FraudData[[#This Row],[velocity_last_24h]],VelocityRules[Velocity Min],VelocityRules[Risk Points],,-1) -> 0 | Q13: =_xlfn.XLOOKUP(FraudData[[#This Row],[merchant_category]],MerchantRules[Merchant Category],MerchantRules[Risk Points],0) -> 0 | R13: =SUM(FraudData[[#This Row],[Amount Risk]:[Merchant Risk]]) -> 3 | S13: {=_xlfn.IFS(FraudData[[#This Row],[Fraud Risk Score]]>=8,"High Risk",FraudData[[#This Row],[Fraud Risk Score]]>=6,"Medium Risk",TRUE,"Low Risk")} -> Low Risk
A14: 13 | B14: 321.56 | C14: 11 | D14: Clothing | E14: 0 | F14: 0 | G14: 73 | H14: 4 | I14: 68 | J14: 0 | K14: =_xlfn.XLOOKUP(FraudData[[#This Row],[amount]],AmountRules[Amount Min],AmountRules[Risk Points],,-1) -> 0 | L14: =_xlfn.XLOOKUP(FraudData[[#This Row],[transaction_hour]],TimeRules[Hour Min],TimeRules[Risk Points],,-1) -> 0 | M14: =_xlfn.XLOOKUP(FraudData[[#This Row],[foreign_transaction]],ForeignRules[Foreign Transaction],ForeignRules[Risk Points],0) -> 0 | N14: =_xlfn.XLOOKUP(FraudData[[#This Row],[location_mismatch]],Table10[Location Mismatch],Table10[Risk Points],0) -> 0 | O14: =_xlfn.XLOOKUP(FraudData[[#This Row],[device_trust_score]],DeviceRules[Device Min],DeviceRules[Risk Points],,-1) -> 0 | P14: =_xlfn.XLOOKUP(FraudData[[#This Row],[velocity_last_24h]],VelocityRules[Velocity Min],VelocityRules[Risk Points],,-1) -> 0 | Q14: =_xlfn.XLOOKUP(FraudData[[#This Row],[merchant_category]],MerchantRules[Merchant Category],MerchantRules[Risk Points],0) -> 0 | R14: =SUM(FraudData[[#This Row],[Amount Risk]:[Merchant Risk]]) -> 0 | S14: {=_xlfn.IFS(FraudData[[#This Row],[Fraud Risk Score]]>=8,"High Risk",FraudData[[#This Row],[Fraud Risk Score]]>=6,"Medium Risk",TRUE,"Low Risk")} -> Low Risk
A15: 14 | B15: 42.96 | C15: 3 | D15: Travel | E15: 0 | F15: 0 | G15: 40 | H15: 2 | I15: 43 | J15: 0 | K15: =_xlfn.XLOOKUP(FraudData[[#This Row],[amount]],AmountRules[Amount Min],AmountRules[Risk Points],,-1) -> 0 | L15: =_xlfn.XLOOKUP(FraudData[[#This Row],[transaction_hour]],TimeRules[Hour Min],TimeRules[Risk Points],,-1) -> 3 | M15: =_xlfn.XLOOKUP(FraudData[[#This Row],[foreign_transaction]],ForeignRules[Foreign Transaction],ForeignRules[Risk Points],0) -> 0 | N15: =_xlfn.XLOOKUP(FraudData[[#This Row],[location_mismatch]],Table10[Location Mismatch],Table10[Risk Points],0) -> 0 | O15: =_xlfn.XLOOKUP(FraudData[[#This Row],[device_trust_score]],DeviceRules[Device Min],DeviceRules[Risk Points],,-1) -> 2 | P15: =_xlfn.XLOOKUP(FraudData[[#This Row],[velocity_last_24h]],VelocityRules[Velocity Min],VelocityRules[Risk Points],,-1) -> 0 | Q15: =_xlfn.XLOOKUP(FraudData[[#This Row],[merchant_category]],MerchantRules[Merchant Category],MerchantRules[Risk Points],0) -> 0 | R15: =SUM(FraudData[[#This Row],[Amount Risk]:[Merchant Risk]]) -> 5 | S15: {=_xlfn.IFS(FraudData[[#This Row],[Fraud Risk Score]]>=8,"High Risk",FraudData[[#This Row],[Fraud Risk Score]]>=6,"Medium Risk",TRUE,"Low Risk")} -> Low Risk
... A10001: 10000 | B10001: 44.06 | C10001: 2 | D10001: Clothing | E10001: 0 | F10001: 0 | G10001: 38 | H10001: 0 | I10001: 66 | J10001: 0 | K10001: =_xlfn.XLOOKUP(FraudData[[#This Row],[amount]],AmountRules[Amount Min],AmountRules[Risk Points],,-1) -> 0 | L10001: =_xlfn.XLOOKUP(FraudData[[#This Row],[transaction_hour]],TimeRules[Hour Min],TimeRules[Risk Points],,-1) -> 3 | M10001: =_xlfn.XLOOKUP(FraudData[[#This Row],[foreign_transaction]],ForeignRules[Foreign Transaction],ForeignRules[Risk Points],0) -> 0 | N10001: =_xlfn.XLOOKUP(FraudData[[#This Row],[location_mismatch]],Table10[Location Mismatch],Table10[Risk Points],0) -> 0 | O10001: =_xlfn.XLOOKUP(FraudData[[#This Row],[device_trust_score]],DeviceRules[Device Min],DeviceRules[Risk Points],,-1) -> 2 | P10001: =_xlfn.XLOOKUP(FraudData[[#This Row],[velocity_last_24h]],VelocityRules[Velocity Min],VelocityRules[Risk Points],,-1) -> 0 | Q10001: =_xlfn.XLOOKUP(FraudData[[#This Row],[merchant_category]],MerchantRules[Merchant Category],MerchantRules[Risk Points],0) -> 0 | R10001: =SUM(FraudData[[#This Row],[Amount Risk]:[Merchant Risk]]) -> 5 | S10001: {=_xlfn.IFS(FraudData[[#This Row],[Fraud Risk Score]]>=8,"High Risk",FraudData[[#This Row],[Fraud Risk Score]]>=6,"Medium Risk",TRUE,"Low Risk")} -> Low Risk

Sheet Dashboard_Data
A1: Risk Level Distribution
A2: Risk Level | B2: Transactions | C2: Percentage
A3: Low Risk | B3: =COUNTIF(FraudData[Risk Level],Dashboard_Data!A3) -> 9057 | C3: =B3/SUM($B$3:$B$5) -> 0.9057
A4: Medium Risk | B4: =COUNTIF(FraudData[Risk Level],Dashboard_Data!A4) -> 683 | C4: =B4/SUM($B$3:$B$5) -> 0.0683
A5: High Risk | B5: =COUNTIF(FraudData[Risk Level],Dashboard_Data!A5) -> 260 | C5: =B5/SUM($B$3:$B$5) -> 0.026
A7: Risk Factor | B7: Risk Multiplier
A8: Device Trust | B8: 21.64
A9: Transaction Velocity | B9: 11.37
A10: Foreign Transaction | B10: 10.96
A11: Transaction Amount | B11: 10.61
A12: Location Mismatch | B12: 9.72
A13: Merchant Category | B13: 1.71
